Workbook

Sheet Executive Report
A1: Executive Security Cost Leakage Assessment™
A2: Security Cost Leakage Index™ (SCLI™) – Executive Assurance Gap™ Decision Engine v1.1
A4: This report estimates the Executive Assurance Gap™, annual Security Cost Leakage exposure, recoverable value range and priority review areas. It is a preliminary decision-support assessment, not an audit finding.
A6: Organisation Profile | D6: Executive Output
A7: Organisation | B7: =Assessment!D5 -> ABC Group Limited | D7: Overall SCLI™ Risk Score | E7: =ROUND(Assessment!K37,1) -> 71.3
A8: Industry | B8: =Assessment!D6 -> Government / Public Infrastructure | D8: Executive Assurance Gap™ | E8: =IF(E7>=75,"Critical",IF(E7>=60,"High",IF(E7>=40,"Moderate","Controlled"))) -> High
A9: Total Sites / Facilities | B9: =Assessment!D7 -> 1250 | D9: Minimum Leakage Estimate | E9: =Calculations!B31 -> 28142990
A10: Guard Force Total | B10: =Assessment!D8 -> 4000 | D10: Likely Leakage Estimate | E10: =Calculations!B32 -> 57600000
A11: Annual Security Contract Value incl. Ad Hoc Services | B11: =Assessment!D9 -> 480000000 | D11: Maximum Exposure Estimate | E11: =Calculations!B33 -> 96000000
A12: Estimated Annual Losses – Low | B12: =Assessment!D10 -> 1400000 | D12: Estimated Recoverable Low | E12: =Calculations!B35 -> 12664346
A13: Estimated Annual Losses – High | B13: =Assessment!D11 -> 2800000 | D13: Estimated Recoverable High | E13: =Calculations!B36 -> 37440000
A14: Internal Security Team Size | B14: =Assessment!D12 -> 9 | D14: Minimum Leakage % | E14: =Calculations!B28 -> 0.05863123
A15: Security Vendors | B15: =Assessment!D13 -> 4 | D15: Likely Leakage % | E15: =Calculations!B29 -> 0.12
A16: Integrated Technology Coverage | B16: =Assessment!D14 -> 0.65 | D16: Maximum Exposure % | E16: =Calculations!B30 -> 0.2
A17: Technology Used for SLA Verification | B17: =Assessment!D15 -> 0.2 | D17: Assessment Confidence | E17: =Calculations!B34 -> 0.5375
A20: Category Risk Scores
A21: Category | B21: Risk Score | C21: Interpretation
A22: Executive Assurance | B22: =Assessment!K32 -> 76.186441 | C22: =IF(B22>=75,"Critical",IF(B22>=60,"High",IF(B22>=40,"Moderate","Controlled"))) -> Critical
A23: Contract and SLA Enforcement | B23: =Assessment!K33 -> 60.76087 | C23: =IF(B23>=75,"Critical",IF(B23>=60,"High",IF(B23>=40,"Moderate","Controlled"))) -> High
A24: Labour Deployment | B24: =Assessment!K34 -> 70.333333 | C24: =IF(B24>=75,"Critical",IF(B24>=60,"High",IF(B24>=40,"Moderate","Controlled"))) -> High
A25: Technology Verification | B25: =Assessment!K35 -> 76.363636 | C25: =IF(B25>=75,"Critical",IF(B25>=60,"High",IF(B25>=40,"Moderate","Controlled"))) -> Critical
A26: Loss, Reporting and Value | B26: =Assessment!K36 -> 78 | C26: =IF(B26>=75,"Critical",IF(B26>=60,"High",IF(B26>=40,"Moderate","Controlled"))) -> Critical
A29: Executive Interpretation
A30: Based on the current responses, the organisation should treat the result as a preliminary indication of the Executive Assurance Gap™ and possible Security Cost Leakage exposure. The assessment does not conclude that money has been lost. It identifies where the organisation may lack sufficient independent evidence to prove that contracted security performance was actually delivered.
A31: The strengthened model integrates the April leakage calculator logic: manual-record reliance, delayed patrol reporting, proof gaps, internal capacity gaps, technology coverage gaps, allowance complexity, guard-force scale, site-count complexity and contract-value complexity now influence the leakage estimate alongside the 20 executive-assurance questions.
A32: The recommended next step is an Independent Executive Security Assurance Review focused on validating the highest-risk categories, testing a representative sample of sites, reconciling supplier performance against the Service Level Agreement, and quantifying validated recoverable or avoidable value.
A35: Recommended Executive Actions
A36: 1 | B36: Validate annual security contract value, including ad hoc services and variations.
A37: 2 | B37: Confirm whether SLA obligations are independently verified or accepted through supplier reporting.
A38: 3 | B38: Review the highest-risk SCLI™ category scores and identify the strongest leakage drivers.
A39: 4 | B39: Run a representative site sample to test the gap between contracted activity and independently verified evidence.
A40: 5 | B40: Use a MOSS assessment to validate actual leakage, evidence, recoverable value and governance remediation priorities.

Sheet Assessment
A1: Executive Security Cost Leakage Assessment™ – SCLI™ v1.1
A2: Executive Assurance Gap™ + Security Cost Leakage Index™ preliminary decision engine. Complete yellow cells only.
A4: ID | B4: Input | C4: Guidance | D4: Response | E4: Unit/Format
A5: C1 | B5: Organisation name | C5: Enter organisation or business unit name | D5: ABC Group Limited | E5: Text
A6: C2 | B6: Industry vertical | C6: Select closest industry | D6: Government / Public Infrastructure | E6: Dropdown
A7: C3 | B7: Total sites / facilities | C7: Count all sites covered by security arrangements | D7: 1250 | E7: Count
A8: C4 | B8: Guard force total | C8: Total contracted guards/officers across all sites and shifts | D8: 4000 | E8: Count
A9: C5 | B9: Annual security contract value incl. ad hoc services | C9: Include guarding, extra services, variations and recurring technology service costs | D9: 480000000 | E9: Currency
A10: C6 | B10: Estimated annual security losses – low | C10: Conservative range for losses, claims, theft, shrinkage or avoidable incidents | D10: 1400000 | E10: Currency
A11: C7 | B11: Estimated annual security losses – high | C11: Upper range for losses, claims, theft, shrinkage or avoidable incidents | D11: 2800000 | E11: Currency
A12: C8 | B12: Internal security team size | C12: Full-time internal staff responsible for security management and governance | D12: 9 | E12: Count
A13: C9 | B13: Number of contracted security vendors | C13: Guarding, monitoring, technology and specialist providers | D13: 4 | E13: Count
A14: C10 | B14: Integrated technology footprint coverage % | C14: Share of geographic footprint covered by integrated surveillance/access/patrol monitoring | D14: 0.65 | E14: Percent
A15: C11 | B15: Technology used for independent SLA verification % | C15: Extent to which security technology is actively used to verify SLA obligations | D15: 0.2 | E15: Percent
A16: C12 | B16: Manual security records for service verification % | C16: Share of service verification dependent on manual registers/OBs/paper records | D16: 0.6 | E16: Percent
A17: C13 | B17: Centralised monitored surveillance coverage % | C17: Sites where surveillance materially supports access/patrol/incident verification | D17: 0.35 | E17: Percent
A18: C14 | B18: Electronic access control coverage % | C18: Sites with usable electronic access control evidence | D18: 0.45 | E18: Percent
... A22: C18 | B22: Proof of guard attendance verification % | C22: Independent proof quality of guard attendance verification | D22: 0.75 | E22: Percent
A23: C19 | B23: Performance allowance paid | C23: YES/NO | D23: YES | E23: YES/NO
A24: C20 | B24: Night allowance paid | C24: YES/NO | D24: YES | E24: YES/NO
A25: C21 | B25: Firearm allowance paid | C25: YES/NO | D25: YES | E25: YES/NO
A26: C22 | B26: Site allowance paid | C26: YES/NO | D26: YES | E26: YES/NO
A27: C23 | B27: National Key Point allowance paid | C27: YES/NO | D27: NO | E27: YES/NO
A31: ID | B31: Category | C31: Question | D31: Response | E31: Weight | F31: Risk Score | G31: Weighted Score | H31: Comment | J31: Output
A32: Q1 | B32: Contract and SLA Enforcement | C32: Do you have a Service Level Agreement as part of the security service agreement? | D32: Yes – partial/basic SLA | E32: 8 | F32: =IFERROR(VLOOKUP(A32&D32,'Scoring Model'!$D$2:$E$200,2,FALSE),0) -> 40 | G32: =E32*F32 -> 320 | J32: Executive Assurance | K32: =SUMIFS($G$32:$G$51,$B$32:$B$51,"Executive Assurance")/SUMIFS($E$32:$E$51,$B$32:$B$51,"Executive Assurance") -> 76.186441
A33: Q2 | B33: Executive Assurance | C33: If the Board asked tomorrow, could management certify that every contracted security service was independently verified over the past 12 months? | D33: Unknown | E33: 10 | F33: =IFERROR(VLOOKUP(A33&D33,'Scoring Model'!$D$2:$E$200,2,FALSE),0) -> 80 | G33: =E33*F33 -> 800 | J33: Contract and SLA Enforcement | K33: =SUMIFS($G$32:$G$51,$B$32:$B$51,"Contract and SLA Enforcement")/SUMIFS($E$32:$E$51,$B$32:$B$51,"Contract and SLA Enforcement") -> 60.76087
A34: Q3 | B34: Executive Assurance | C34: How much of your annual security expenditure is independently verified rather than accepted through supplier reporting? | D34: 21–40% | E34: 9 | F34: =IFERROR(VLOOKUP(A34&D34,'Scoring Model'!$D$2:$E$200,2,FALSE),0) -> 70 | G34: =E34*F34 -> 630 | J34: Labour Deployment | K34: =SUMIFS($G$32:$G$51,$B$32:$B$51,"Labour Deployment")/SUMIFS($E$32:$E$51,$B$32:$B$51,"Labour Deployment") -> 70.333333
A35: Q4 | B35: Contract and SLA Enforcement | C35: If your largest guarding contract was audited tomorrow, what percentage of contractual obligations could be supported by independently verified evidence? | D35: 0–20% | E35: 9 | F35: =IFERROR(VLOOKUP(A35&D35,'Scoring Model'!$D$2:$E$200,2,FALSE),0) -> 90 | G35: =E35*F35 -> 810 | J35: Technology Verification | K35: =SUMIFS($G$32:$G$51,$B$32:$B$51,"Technology Verification")/SUMIFS($E$32:$E$51,$B$32:$B$51,"Technology Verification") -> 76.363636
A36: Q5 | B36: Contract and SLA Enforcement | C36: How much money did the organisation recover through SLA penalties or service credits during the past financial year? | D36: Less than 1% of annual contract value | E36: 8 | F36: =IFERROR(VLOOKUP(A36&D36,'Scoring Model'!$D$2:$E$200,2,FALSE),0) -> 70 | G36: =E36*F36 -> 560 | J36: Loss, Reporting and Value | K36: =SUMIFS($G$32:$G$51,$B$32:$B$51,"Loss, Reporting and Value")/SUMIFS($E$32:$E$51,$B$32:$B$51,"Loss, Reporting and Value") -> 78
A37: Q6 | B37: Labour Deployment | C37: Has the security deployment model been independently validated against current operational risk during the past 24 months? | D37: Unknown | E37: 8 | F37: =IFERROR(VLOOKUP(A37&D37,'Scoring Model'!$D$2:$E$200,2,FALSE),0) -> 75 | G37: =E37*F37 -> 600 | J37: Overall SCLI Risk Score | K37: =SUM($G$32:$G$51)/SUM($E$32:$E$51) -> 71.305732
A38: Q7 | B38: Labour Deployment | C38: How many guard posts currently exist mainly because they have always existed? | D38: Unknown | E38: 7 | F38: =IFERROR(VLOOKUP(A38&D38,'Scoring Model'!$D$2:$E$200,2,FALSE),0) -> 65 | G38: =E38*F38 -> 455 | J38: Contract Value | K38: =D9 -> 480000000
A39: Q8 | B39: Executive Assurance | C39: How reliant is your organisation on manual security records for service verification? | D39: High reliance | E39: 8 | F39: =IFERROR(VLOOKUP(A39&D39,'Scoring Model'!$D$2:$E$200,2,FALSE),0) -> 70 | G39: =E39*F39 -> 560 | J39: Assessment Coverage Quality | K39: =Calculations!B34 -> 0.5375
A40: Q9 | B40: Technology Verification | C40: If security enabling technology is integrated, how much of the geographical footprint is effectively covered? | D40: 21–40% | E40: 7 | F40: =IFERROR(VLOOKUP(A40&D40,'Scoring Model'!$D$2:$E$200,2,FALSE),0) -> 70 | G40: =E40*F40 -> 490 | J40: Minimum Leakage % | K40: =Calculations!B28 -> 0.05863123
A41: Q10 | B41: Technology Verification | C41: To what extent is security enabling technology actively used for independent verification of SLA obligations? | D41: 21–40% | E41: 8 | F41: =IFERROR(VLOOKUP(A41&D41,'Scoring Model'!$D$2:$E$200,2,FALSE),0) -> 70 | G41: =E41*F41 -> 560 | J41: Likely Leakage % | K41: =Calculations!B29 -> 0.12
A42: Q11 | B42: Executive Assurance | C42: Do executive reports include an independent assurance score or evidence-based performance view rather than only operational activity? | D42: No – mostly activity reporting | E42: 8 | F42: =IFERROR(VLOOKUP(A42&D42,'Scoring Model'!$D$2:$E$200,2,FALSE),0) -> 80 | G42: =E42*F42 -> 640 | J42: Maximum Exposure % | K42: =Calculations!B30 -> 0.2
A43: Q12 | B43: Loss, Reporting and Value | C43: Are security incidents and losses reconciled against SLA performance, contractor obligations and potential penalties? | D43: Unknown | E43: 7 | F43: =IFERROR(VLOOKUP(A43&D43,'Scoring Model'!$D$2:$E$200,2,FALSE),0) -> 70 | G43: =E43*F43 -> 490 | J43: Estimated Minimum Leakage | K43: =Calculations!B31 -> 28142990
A44: Q13 | B44: Contract and SLA Enforcement | C44: Are ad hoc additional security services formally approved, tracked and reconciled against contract terms? | D44: Some post-facto review | E44: 6 | F44: =IFERROR(VLOOKUP(A44&D44,'Scoring Model'!$D$2:$E$200,2,FALSE),0) -> 45 | G44: =E44*F44 -> 270 | J44: Estimated Likely Leakage | K44: =Calculations!B32 -> 57600000
A45: Q14 | B45: Executive Assurance | C45: Are supplier reports independently sampled or validated every month across a representative site set? | D45: Rarely | E45: 8 | F45: =IFERROR(VLOOKUP(A45&D45,'Scoring Model'!$D$2:$E$200,2,FALSE),0) -> 75 | G45: =E45*F45 -> 600 | J45: Estimated Maximum Exposure | K45: =Calculations!B33 -> 96000000
A46: Q15 | B46: Contract and SLA Enforcement | C46: Is supplier non-performance linked to formal consequence management in monthly or quarterly governance forums? | D46: Partial/inconsistent | E46: 7 | F46: =IFERROR(VLOOKUP(A46&D46,'Scoring Model'!$D$2:$E$200,2,FALSE),0) -> 45 | G46: =E46*F46 -> 315 | J46: Estimated Recoverable Low | K46: =Calculations!B35 -> 12664346
A47: Q16 | B47: Technology Verification | C47: Does your PMIS / technology stack cover the entire organisation sufficiently to support independent service verification? | D47: 0–20% | E47: 7 | F47: =IFERROR(VLOOKUP(A47&D47,'Scoring Model'!$D$2:$E$200,2,FALSE),0) -> 90 | G47: =E47*F47 -> 630 | J47: Estimated Recoverable High | K47: =Calculations!B36 -> 37440000
...

Sheet Scoring Model
A1: Question ID | B1: Response Option | C1: Category | D1: Lookup Key | E1: Risk Score
A2: Q1 | B2: Yes – comprehensive SLA | C2: Contract and SLA Enforcement | D2: Q1Yes – comprehensive SLA | E2: 0
A3: Q1 | B3: Yes – partial/basic SLA | C3: Contract and SLA Enforcement | D3: Q1Yes – partial/basic SLA | E3: 40
A4: Q1 | B4: No formal SLA | C4: Contract and SLA Enforcement | D4: Q1No formal SLA | E4: 90
A5: Q1 | B5: Unknown | C5: Contract and SLA Enforcement | D5: Q1Unknown | E5: 75
A6: Q2 | B6: Yes | C6: Executive Assurance | D6: Q2Yes | E6: 0
A7: Q2 | B7: Partially | C7: Executive Assurance | D7: Q2Partially | E7: 50
A8: Q2 | B8: No | C8: Executive Assurance | D8: Q2No | E8: 95
A9: Q2 | B9: Unknown | C9: Executive Assurance | D9: Q2Unknown | E9: 80
A10: Q3 | B10: 0–20% | C10: Executive Assurance | D10: Q30–20% | E10: 90
A11: Q3 | B11: 21–40% | C11: Executive Assurance | D11: Q321–40% | E11: 70
A12: Q3 | B12: 41–60% | C12: Executive Assurance | D12: Q341–60% | E12: 50
A13: Q3 | B13: 61–80% | C13: Executive Assurance | D13: Q361–80% | E13: 25
... A94: Q20 | B94: Unknown | C94: Contract and SLA Enforcement | D94: Q20Unknown | E94: 75

Sheet Assumptions
A1: Model Assumptions and Weightings | B1: Value | C1: Format | D1: Description
A2: Minimum leakage base floor | B2: 0.01 | C2: percent | D2: Conservative leakage floor present in large outsourced guarding environments.
A3: Minimum leakage | Manual record weight | B3: 0.025 | C3: percent | D3: Higher manual dependence raises unverifiable service delivery risk.
A4: Minimum leakage | Delayed patrol reporting weight | B4: 0.015 | C4: percent | D4: After-shift or monthly review weakens recoverability and timely correction.
A5: Minimum leakage | Supervisory proof gap weight | B5: 0.03 | C5: percent | D5: Lower proof of supervisory visits raises baseline leakage risk.
A6: Minimum leakage | Attendance proof gap weight | B6: 0.007 | C6: percent | D6: Lower proof of attendance verification raises baseline leakage risk.
A7: Minimum leakage | Internal capacity gap weight | B7: 0.005 | C7: percent | D7: Insufficient internal governance headcount raises baseline risk.
A8: Minimum leakage | Scale complexity weight | B8: 0.004 | C8: percent | D8: Guard force, spend, premises count, and footprint complexity create coordination risk.
A9: Minimum leakage | Allowance complexity weight | B9: 0.003 | C9: percent | D9: More active allowance types raise baseline validation complexity.
A10: Likely reality | Surveillance gap weight | B10: 0.03 | C10: percent | D10: Limited monitored surveillance coverage reduces proof quality.
A11: Likely reality | Access control gap weight | B11: 0.025 | C11: percent | D11: Limited central access control coverage reduces certainty.
A12: Likely reality | Electronic record monitoring gap weight | B12: 0.01 | C12: percent | D12: Electronic data not centrally monitored loses much of its value.
A13: Likely reality | Real-time patrol gap weight | B13: 0.008 | C13: percent | D13: Missing real-time patrol visibility increases variance between invoice and delivery.
... A34: Recoverable high factor | B34: 0.65 | C34: percent | D34: Conservative recoverable portion of likely leakage.

Sheet Calculations
A1: Model Calculations | B1: Value | C1: Format | D1: Description
A2: Annual security contract value | B2: =Assessment!D9 -> 480000000 | C2: currency | D2: Contract value inclusive of guarding, ad hoc services and recurring service costs.
A3: Protected premises | B3: =Assessment!D7 -> 1250 | C3: count | D3: Total facilities / sites in scope.
A4: Guard force | B4: =Assessment!D8 -> 4000 | C4: count | D4: Outsourced guard force in scope.
A5: Geographical footprint | B5: =MIN(9,Assessment!D7/50) -> 9 | C5: count | D5: Estimated region complexity proxy derived from total sites.
A6: Surveillance gap | B6: =1-Assessment!D17 -> 0.65 | C6: percent | D6: Share lacking centrally monitored surveillance proof.
A7: Access control gap | B7: =1-Assessment!D18 -> 0.55 | C7: percent | D7: Share lacking usable access control evidence.
A8: Electronic record monitoring gap | B8: =1-Assessment!D14 -> 0.35 | C8: percent | D8: Share of footprint not covered by integrated technology.
A9: Manual record risk | B9: =Assessment!D16 -> 0.6 | C9: percent | D9: Share dependent on manual evidence.
A10: Real-time patrol monitoring gap | B10: =1-Assessment!D19 -> 0.75 | C10: percent | D10: Share lacking real-time patrol monitoring.
A11: Delayed patrol reporting risk | B11: =Assessment!D20 -> 0.5 | C11: percent | D11: Delayed patrol reporting exposure.
A12: Required internal security headcount | B12: =MAX(1,ROUNDUP(B3/Assumptions!B29,0)) -> 313 | C12: count | D12: Target internal oversight headcount for current site count.
A13: Internal capacity gap | B13: =MAX(0,(B12-Assessment!D12)/B12) -> 0.97124601 | C13: percent | D13: Shortfall between required and actual oversight headcount.
A14: Supervisory proof gap | B14: =1-Assessment!D21 -> 0.45 | C14: percent | D14: Share of supervisory visits not independently evidenced.
A15: Attendance proof gap | B15: =1-Assessment!D22 -> 0.25 | C15: percent | D15: Share of attendance verification not independently evidenced.
A16: Allowance complexity score | B16: =AVERAGE(IF(Assessment!D23="YES",1,0),IF(Assessment!D24="YES",1,0),IF(Assessment!D25="YES",1,0),IF(Assessment!D26="YES",1,0),IF(Assessment!D27="YES",1,0)) -> 0.8 | C16: percent | D16: Average complexity created by active allowance types.
A17: Guard force scale | B17: =MIN(1,B4/Assumptions!B25) -> 1 | C17: percent | D17: Normalised guard-force complexity.
A18: Cost scale | B18: =MIN(1,B2/Assumptions!B26) -> 1 | C18: percent | D18: Normalised spend complexity.
A19: Premises scale | B19: =MIN(1,B3/Assumptions!B27) -> 0.625 | C19: percent | D19: Normalised site-count complexity.
A20: Footprint scale | B20: =MIN(1,B5/Assumptions!B28) -> 1 | C20: percent | D20: Normalised geographic complexity.
A21: Composite scale complexity | B21: =AVERAGE(B17:B20) -> 0.90625 | C21: percent | D21: Average normalised scale complexity.
A22: Questionnaire Risk Factor | B22: =Assessment!K37/100 -> 0.71305732 | C22: percent | D22: Overall SCLI questionnaire risk converted to percentage.
A23: Loss Pressure Factor | B23: =MIN(1,AVERAGE(Assessment!D10:'Assessment'!D11)/MAX(1,B2)) -> 0.004375 | C23: percent | D23: Reported losses as a percentage of annual contract value.
A24: Technology Verification Gap | B24: =1-(Assessment!D14*Assessment!D15) -> 0.87 | C24: percent | D24: Simplified view of footprint coverage and verification utilisation gap.
A25: Coverage Quality | B25: =AVERAGE(Assessment!D14,Assessment!D15,Assessment!D21,Assessment!D22) -> 0.5375 | C25: percent | D25: Composite evidence quality score.
A27: Leakage Bands
A28: Minimum guaranteed leakage % | B28: =MIN(Assumptions!B30,Assumptions!B2+(B9*Assumptions!B3)+(B11*Assumptions!B4)+(B14*Assumptions!B5)+(B15*Assumptions!B6)+(B13*Assumptions!B7)+(B21*Assumptions!B8)+(B16*Assumptions!B9)) -> 0.05863123 | C28: percent | D28: Baseline leakage expected before detailed verification.
A29: Likely reality leakage % | B29: =MIN(Assumptions!B31,B28+(B6*Assumptions!B10)+(B7*Assumptions!B11)+(B8*Assumptions!B12)+(B10*Assumptions!B13)+(B9*Assumptions!B14)+(B21*Assumptions!B15)+(B16*Assumptions!B16)+(B22*0.03)) -> 0.12 | C29: percent | D29: Expected leakage under current control, monitoring and assurance conditions.
A30: Maximum exposure leakage % | B30: =MIN(Assumptions!B32,B29+(B9*Assumptions!B17)+(B11*Assumptions!B18)+(B14*Assumptions!B19)+(B15*Assumptions!B20)+(B6*Assumptions!B21)+(B8*Assumptions!B22)+(B13*Assumptions!B23)+(B16*Assumptions!B24)+(B22*0.04)) -> 0.2 | C30: percent | D30: Upper credible exposure where assurance failures compound.
A31: Minimum guaranteed leakage | B31: =B2*B28 -> 28142990 | C31: currency | D31: Annual minimum leakage derived from annual contract value x minimum leakage rate.
A32: Likely reality leakage | B32: =B2*B29 -> 57600000 | C32: currency | D32: Annual likely leakage derived from annual contract value x likely leakage rate.
A33: Maximum exposure leakage | B33: =B2*B30 -> 96000000 | C33: currency | D33: Annual maximum exposure derived from annual contract value x maximum exposure rate.
A34: Assessment confidence | B34: =MAX(0.35,MIN(0.9,B25)) -> 0.5375 | C34: percent | D34: Preliminary confidence based on evidence coverage, proof quality and data completeness.
A35: Estimated recoverable value low | B35: =B31*Assumptions!B33 -> 12664346 | C35: currency | D35: Conservative recoverable value based on minimum leakage.
A36: Estimated recoverable value high | B36: =B32*Assumptions!B34 -> 37440000 | C36: currency | D36: Conservative recoverable value based on likely leakage.
A37: Likely leakage per protected premise | B37: =B32/MAX(1,B3) -> 46080 | C37: currency | D37: Average likely annual leakage per protected premise.
A38: Security contract value per protected premise | B38: =B2/MAX(1,B3) -> 384000 | C38: currency | D38: Average annual contract value per protected premise.

Sheet Lists
A1: Industry Verticals | C1: YES/NO
A2: Telecommunications | C2: YES
A3: Mining | C3: NO
A4: Energy / Utilities
A5: Ports and Logistics
A6: Manufacturing
A7: Retail
A8: Financial Services
A9: Data Centres
A10: Government / Public Infrastructure
A11: Healthcare
A12: Other

Sheet Methodology Notes
A1: Methodology Notes – SCLI™ v1.1
A2: Model status | B2: Preliminary executive decision-support model. Not an audit finding.
A3: Primary purpose | B3: Estimate likely Security Cost Leakage arising from the Executive Assurance Gap™.
A4: Key refinement from April calculator | B4: Integrated calibration variables: guard force scale, contract value scale, premises complexity, manual record reliance, delayed patrol reporting, proof gaps, internal capacity gap, technology coverage gap and allowance complexity.
A5: Key refinement from June assessment | B5: Integrated executive assurance questions, SLA enforcement questions, technology verification questions and Board-certification questions.
A6: Core financial input | B6: Annual security contract value inclusive of guarding, ad hoc additional services, variations and recurring security technology service costs.
A7: Leakage bands | B7: Minimum, likely and maximum exposure bands are calculated using calibration variables and questionnaire risk factors.
A8: Recoverable value | B8: Preliminary recoverable value estimates use conservative recovery factors and must be validated through an Independent Executive Security Assurance Review.
A9: Validation path | B9: Use MOSS assessment to validate estimated leakage, evidence and recommendations.
A10: Currency format standard | B10: All money values are formatted as R#,##0.00, for example R2,600,000.00.
A11: Version | B11: SCLI™ v1.1 – 26 June 2026
